Workbook
Name cause: #REF!
Name Comments: #REF!
Name FunctionalityImpPercentage: [1]Formulas!$C$19
Name GrandTotal: '[2]Server HW Details'!#REF!
Name Ltst_TestLog: "'Test log'"
Name Severity: #REF!
Name State_of_Origin: #REF!

Sheet Report
A2: On the Job Training Assessment Report
A4: Employee ID | E4: Employee Name | J4: Assessment Date
A6: 2081120 | E6: Venkatesh.Bandaru@cognizant.com | J6: 13/1/2026
A7: OJT Name | E7: Developing Single Page Application Using React -On-The-Job Evaluation [201-INTERMEDIATE]
A8: This is to certify that he/she has
A10: =IF(('Metric Test Case'!G101)>60,"COMPLETED","Not COMPLETED") -> Not COMPLETED
A11: Web Application Development using React JS - Social Connect - PL2 - ATHDW309473
A12: Overall Report
A13: Areas of Excellence
A14: =SUBSTITUTE(SUBSTITUTE(SUBSTITUTE(SUBSTITUTE(CONCATENATE( IF('Skill Cluster'!B3="Areas of Excellence",'Skill Cluster'!A3),", ", IF('Skill Cluster'!B4="Areas of Excellence",'Skill Cluster'!A4),", ", IF('Skill Cluster'!B5="Areas of Excellence",'Skill Cluster'!A5),", ", IF('Skill Cluster'!B6="Areas of Excellence",'Skill Cluster'!A6),", ", IF('Skill Cluster'!B7="Areas of Excellence",'Skill Cluster'!A7) )," FALSE,",""),", FALSE",""),"FALSE, ",""),"FALSE","")
A18: Areas of Improvement
A19: =SUBSTITUTE(SUBSTITUTE(SUBSTITUTE(SUBSTITUTE(CONCATENATE( IF('Skill Cluster'!B3="Areas of Improvement",'Skill Cluster'!A3),", ", IF('Skill Cluster'!B4="Areas of Improvement",'Skill Cluster'!A4),", ", IF('Skill Cluster'!B5="Areas of Improvement",'Skill Cluster'!A5),", ", IF('Skill Cluster'!B6="Areas of Improvement",'Skill Cluster'!A6),", ", IF('Skill Cluster'!B7="Areas of Improvement",'Skill Cluster'!A7) )," FALSE,",""),", FALSE",""),"FALSE, ",""),"FALSE","") -> Develop User interfaces for all the pages, API Implementations, Developing Reusable Components
A24: Areas of Focus
A25: =SUBSTITUTE(SUBSTITUTE(SUBSTITUTE(SUBSTITUTE(CONCATENATE( IF('Skill Cluster'!B3="Areas of Focus",'Skill Cluster'!A3),", ", IF('Skill Cluster'!B4="Areas of Focus",'Skill Cluster'!A4),", ", IF('Skill Cluster'!B5="Areas of Focus",'Skill Cluster'!A5),", ", IF('Skill Cluster'!B6="Areas of Focus",'Skill Cluster'!A6),", ", IF('Skill Cluster'!B7="Areas of Focus",'Skill Cluster'!A7) )," FALSE,",""),", FALSE",""),"FALSE, ",""),"FALSE","") -> Functionalities, Performance Best practices / Others

Sheet Metric Test Case
A1: React JS - PL2-Social Connect Metrics Test Cases | J1: 0.5 | L1: Alternate Approach | M1: 0.5
A2: Business Requirements | B2: Web Page / Class Affected /Test scenario | C2: Code Snippet to be checked / Expected Result | D2: Weightage | E2: Topic | F2: Topic Score | H2: Comments
A4: Design UI : Develop User interfaces for all the pages as per the business requirements | B4: Create UI for all the screens | D4: =SUM(D5:D33) -> 30 | F4: Result | G4: =SUM(G5:G33) -> 23
B5: Header | C5: The header must prominently display the Social Connect logo for consistent branding and identity across all pages. It should be responsive, adapting to various screen sizes and devices for a seamless user experience on desktop and mobile platforms. | D5: 2 | E5: ● Apply and build the application using the core React concepts. ● Apply state management concepts and build th+C19+E5 | F5: PASS | G5: =IF(F5="PASS",$D5,IF(F5="Alternate Approach/Partial Implementation",($J$1*$D5),0)) -> 2
B6: User Details with Bio | C6: Visual Layout: Design a visually appealing layout to showcase the user's profile picture, name, username, and relevant details. | D6: 1 | F6: PASS | G6: =IF(F6="PASS",$D6,IF(F6="Alternate Approach/Partial Implementation",($J$1*$D6),0)) -> 1
C7: User Information: Display key user information, such as age, location, interests, and any other pertinent details. | D7: 1 | F7: PASS | G7: =IF(F7="PASS",$D7,IF(F7="Alternate Approach/Partial Implementation",($J$1*$D7),0)) -> 1
C8: UI Components: Utilize appropriate UI components like cards, sections, or tabs to organize different aspects of the user's information. | D8: 1 | F8: PASS | G8: =IF(F8="PASS",$D8,IF(F8="Alternate Approach/Partial Implementation",($J$1*$D8),0)) -> 1
C9: Bio Content: Provide a designated section for the user's biography, allowing them to describe themselves, their interests, or any other relevant information. | D9: 1 | F9: PASS | G9: =IF(F9="PASS",$D9,IF(F9="Alternate Approach/Partial Implementation",($J$1*$D9),0)) -> 1
C10: Formatting and Styling: Design the bio page with proper formatting and styling, including paragraph breaks, bullet points, or emphasis on important details. | D10: 1 | F10: PASS | G10: =IF(F10="PASS",$D10,IF(F10="Alternate Approach/Partial Implementation",($J$1*$D10),0)) -> 1
C11: Readability: Ensure the bio content is presented in a readable format, avoiding clutter and excessive text. | D11: 1 | F11: PASS | G11: =IF(F11="PASS",$D11,IF(F11="Alternate Approach/Partial Implementation",($J$1*$D11),0)) -> 1
B12: Cover Page | C12: Visual Appeal: Design an attractive and visually appealing cover page layout that complements the overall aesthetic of the application. | D12: 1 | F12: PASS | G12: =IF(F12="PASS",$D12,IF(F12="Alternate Approach/Partial Implementation",($J$1*$D12),0)) -> 1
C13: Integration with User Profile: Ensure that the cover photo seamlessly integrates with the user's profile page, providing a cohesive user experience. | D13: 1 | F13: PASS | G13: =IF(F13="PASS",$D13,IF(F13="Alternate Approach/Partial Implementation",($J$1*$D13),0)) -> 1
C14: Differentiate Banner and Avatar: Create separate sections or folders to store the cover photo (banner) and user's profile picture (avatar) for easy management. | D14: 1 | F14: PASS | G14: =IF(F14="PASS",$D14,IF(F14="Alternate Approach/Partial Implementation",($J$1*$D14),0)) -> 1
C15: User Upload: Allow users to upload their own cover photo from their local device or select from pre-defined options. | D15: 1 | F15: FAIL | G15: =IF(F15="PASS",$D15,IF(F15="Alternate Approach/Partial Implementation",($J$1*$D15),0)) -> 0 | H15: Change Cover button is present with camera icon and proper styling.Button lacks onClick event handler and file input mechanism - feature not implemented.
C16: User Interaction: Provide a user-friendly interface for selecting or uploading a cover photo, allowing users to preview and confirm their selection. | D16: 1 | F16: FAIL | G16: =IF(F16="PASS",$D16,IF(F16="Alternate Approach/Partial Implementation",($J$1*$D16),0)) -> 0 | H16: Change Cover button is present with camera icon and proper styling.Button lacks onClick event handler and file input mechanism - feature not implemented.
B17: Adding Post | C17: Message Box: Design a user-friendly message box for post content, supporting text, emojis, and rich media. | D17: 1 | F17: PASS | G17: =IF(F17="PASS",$D17,IF(F17="Alternate Approach/Partial Implementation",($J$1*$D17),0)) -> 1
C18: Image Attachment: Provide a mechanism for users to select and attach images from the application's asset folder to their posts. | D18: 1 | F18: FAIL | G18: =IF(F18="PASS",$D18,IF(F18="Alternate Approach/Partial Implementation",($J$1*$D18),0)) -> 0 | H18: Photo/Video button displays correctly with image icon in post creation form.Button has no click event binding and no file upload logic - feature not implemented.
C19: User Interface: Create a clear and intuitive user interface that guides users through the post creation process. | D19: 1 | F19: Alternate Approach/Partial implementation | G19: =IF(F19="PASS",$D19,IF(F19="Alternate Approach/Partial Implementation",($J$1*$D19),0)) -> 0.5 | H19: Basic text posting works but guided workflow and validation missing
C20: Responsive Layout: Ensure a responsive layout adaptable to different screen sizes and devices for a consistent user experience. | D20: 1 | F20: PASS | G20: =IF(F20="PASS",$D20,IF(F20="Alternate Approach/Partial Implementation",($J$1*$D20),0)) -> 1
C21: Rendering and Display: Display user posts in visually appealing and user-friendly sections of the application. | D21: 1 | F21: PASS | G21: =IF(F21="PASS",$D21,IF(F21="Alternate Approach/Partial Implementation",($J$1*$D21),0)) -> 1
B22: Feed Area | C22: User-Friendly Layout: Design a visually appealing and user-friendly layout to present the posts in the feed area. | D22: 1 | F22: PASS | G22: =IF(F22="PASS",$D22,IF(F22="Alternate Approach/Partial Implementation",($J$1*$D22),0)) -> 1
C23: Post Content: Ensure that the post content, including the message, author, timestamp, and any attached images, is properly displayed and easily readable. | D23: 1 | F23: FAIL | G23: =IF(F23="PASS",$D23,IF(F23="Alternate Approach/Partial Implementation",($J$1*$D23),0)) -> 0 | H23: Photo/Video button has no click handler or file upload
C24: Pagination: Consider implementing pagination or infinite scrolling to manage large volumes of posts efficiently. | D24: 1 | F24: FAIL | G24: =IF(F24="PASS",$D24,IF(F24="Alternate Approach/Partial Implementation",($J$1*$D24),0)) -> 0 | H24: No pagination or No infinite scrolling logic implemented
C25: Comment Section: Include a comment section beneath each post where users can leave comments and engage in discussions. | D25: 1 | F25: PASS | G25: =IF(F25="PASS",$D25,IF(F25="Alternate Approach/Partial Implementation",($J$1*$D25),0)) -> 1
C26: Comment Count: Display the total number of comments on a post to provide a sense of engagement and activity. | D26: 1 | F26: PASS | G26: =IF(F26="PASS",$D26,IF(F26="Alternate Approach/Partial Implementation",($J$1*$D26),0)) -> 1
B27: Friends List | C27: User-Friendly Layout: Design an intuitive and visually appealing interface to display the user's list of friends. | D27: 1 | F27: PASS | G27: =IF(F27="PASS",$D27,IF(F27="Alternate Approach/Partial Implementation",($J$1*$D27),0)) -> 1
C28: Friend Details: Include relevant information about each friend, such as their profile picture, name, and any additional details that promote recognition and interaction. | D28: 1 | F28: PASS | G28: =IF(F28="PASS",$D28,IF(F28="Alternate Approach/Partial Implementation",($J$1*$D28),0)) -> 1
B29: Add User (Friends) | C29: User-Friendly Interface: Design a modal popup that allows users to enter basic information about the new user they want to add. | D29: 1 | F29: PASS | G29: =IF(F29="PASS",$D29,IF(F29="Alternate Approach/Partial Implementation",($J$1*$D29),0)) -> 1
C30: Form Fields: Include relevant fields for capturing the basic information, such as name, profile picture, email, and any other necessary details. | D30: 1 | F30: Alternate Approach/Partial implementation | G30: =IF(F30="PASS",$D30,IF(F30="Alternate Approach/Partial Implementation",($J$1*$D30),0)) -> 0.5 | H30: profile picture upload missing
C31: Submit Button: Provide a button to submit the user's information and add them to the friends list. | D31: 1 | F31: PASS | G31: =IF(F31="PASS",$D31,IF(F31="Alternate Approach/Partial Implementation",($J$1*$D31),0)) -> 1
C32: User Experience: Display the add user functionality within a modal popup to provide a focused and intuitive user experience. | D32: 1 | F32: PASS | G32: =IF(F32="PASS",$D32,IF(F32="Alternate Approach/Partial Implementation",($J$1*$D32),0)) -> 1
C33: Visual Feedback: Provide visual feedback to indicate the successful addition of the new user, ensuring the user is aware that the process has completed successfully. | D33: 1 | F33: FAIL | G33: =IF(F33="PASS",$D33,IF(F33="Alternate Approach/Partial Implementation",($J$1*$D33),0)) -> 0 | H33: No success notification/toast
A35: API Implementations | B35: Use API calls to fetch and show the data as per the need | D35: =SUM(D36:D46) -> 10 | G35: =SUM(G36:G46) -> 6.5
B36: Fetch Users | C36: Fetches a list of users from the backend server | D36: 1 | E36: • API Integration | F36: PASS | G36: =IF(F36="PASS",$D36,IF(F36="Alternate Approach/Partial Implementation",($J$1*$D36),0)) -> 1
B37: Retrieve Posts | C37: Retrieves a list of posts from the backend server. | D37: 1 | F37: PASS | G37: =IF(F37="PASS",$D37,IF(F37="Alternate Approach/Partial Implementation",($J$1*$D37),0)) -> 1
B38: Create Post | C38: Creates a new post and stores it in the backend database. | D38: 1 | F38: PASS | G38: =IF(F38="PASS",$D38,IF(F38="Alternate Approach/Partial Implementation",($J$1*$D38),0)) -> 1
B39: Update User | C39: Updates user information in the backend database. | D39: 1 | F39: PASS | G39: =IF(F39="PASS",$D39,IF(F39="Alternate Approach/Partial Implementation",($J$1*$D39),0)) -> 1
B40: Delete Post | C40: Deletes a specific post from the backend database. | D40: 1 | F40: FAIL | G40: =IF(F40="PASS",$D40,IF(F40="Alternate Approach/Partial Implementation",($J$1*$D40),0)) -> 0 | H40: NOT IMPLEMENTED
B41: Add Friend | C41: Adds a new user as a friend to the current user's friends list in the backend. | D41: 1 | F41: PASS | G41: =IF(F41="PASS",$D41,IF(F41="Alternate Approach/Partial Implementation",($J$1*$D41),0)) -> 1
B42: Get Friends | C42: Retrieves the list of friends for the current user from the backend server. | D42: 1 | F42: PASS | G42: =IF(F42="PASS",$D42,IF(F42="Alternate Approach/Partial Implementation",($J$1*$D42),0)) -> 1
...

Sheet Skill Cluster
A1: Skill Cluster
A2: Features | B2: Status | C2: Weightage | D2: Score | E2: Topicwise %
A3: Develop User interfaces for all the pages | B3: =IF((D3/C3*100)>=80,"Areas of Excellence",IF(AND((D3/C3*100)>=60,(D3/C3*100)<80),"Areas of improvement","Areas of Focus")) -> Areas of improvement | C3: ='Metric Test Case'!D4 -> 30 | D3: ='Metric Test Case'!G4 -> 23 | E3: =(D3/C3)*100 -> 76.666667
A4: API Implementations | B4: =IF((D4/C4*100)>=80,"Areas of Excellence",IF(AND((D4/C4*100)>=60,(D4/C4*100)<80),"Areas of improvement","Areas of Focus")) -> Areas of improvement | C4: ='Metric Test Case'!D35 -> 10 | D4: ='Metric Test Case'!G35 -> 6.5 | E4: =(D4/C4)*100 -> 65
A5: Functionalities | B5: =IF((D5/C5*100)>=80,"Areas of Excellence",IF(AND((D5/C5*100)>=60,(D5/C5*100)<80),"Areas of improvement","Areas of Focus")) -> Areas of Focus | C5: ='Metric Test Case'!D48 -> 40 | D5: ='Metric Test Case'!G48 -> 16 | E5: =(D5/C5)*100 -> 40
A6: Developing Reusable Components | B6: =IF((D6/C6*100)>=80,"Areas of Excellence",IF(AND((D6/C6*100)>=60,(D6/C6*100)<80),"Areas of improvement","Areas of Focus")) -> Areas of improvement | C6: ='Metric Test Case'!D90 -> 10 | D6: ='Metric Test Case'!G90 -> 6 | E6: =(D6/C6)*100 -> 60
A7: Performance Best practices / Others | B7: =IF((D7/C7*100)>=80,"Areas of Excellence",IF(AND((D7/C7*100)>=60,(D7/C7*100)<80),"Areas of improvement","Areas of Focus")) -> Areas of Focus | C7: ='Metric Test Case'!D97 -> 10 | D7: ='Metric Test Case'!G97 -> 5 | E7: =(D7/C7)*100 -> 50
C8: =SUM(C3:C7) -> 100 | D8: =SUM(D3:D7) -> 56.5

Sheet formuls
A1: PASS
A2: FAIL
A3: Not Evaluated
A4: Alternate Approach/Partial implementation
